<?xml version="1.0" ?>
<!-- =================================================================================== -->
<!-- |    This document was autogenerated by xacro from neptr.xacro                    | -->
<!-- |    EDITING THIS FILE BY HAND IS NOT RECOMMENDED                                 | -->
<!-- =================================================================================== -->
<robot name="neptr">
  <!-- Dummy link to avoid inertia issue with root link -->
  <link name="dummy_link"/>
  <joint name="dummy_joint" type="fixed">
    <parent link="dummy_link"/>
    <child link="base_link"/>
    <origin xyz="0 0 0" rpy="0 0 0"/>
  </joint>
  <link name="base_link">
    <visual>
      <geometry>
        <box size="0.1 0.1 0.1"/>
      </geometry>
      <material name="base_link_material">
        <color rgba="0.8 0.8 0.8 1.0"/>
      </material>
    </visual>
  </link>
  <joint name="joint1" type="revolute">
    <parent link="base_link"/>
    <child link="link1"/>
    <origin xyz="0 0 0.1" rpy="0 0 0"/>
    <axis xyz="0 1 0"/>
    <limit effort="100" lower="-1.57" upper="1.57" velocity="1.0"/>
  </joint>
  <link name="link1">
    <visual>
      <geometry>
        <box size="0.1 0.1 0.1"/>
      </geometry>
      <material name="link1_material">
        <color rgba="0.8 0.8 0.8 1.0"/>
      </material>
    </visual>
  </link>
  <!-- Upper Leg -->
  <link name="upper_leg">
    <inertial>
      <origin rpy="0 0 0" xyz="0 0 0"/>
      <mass value="1.0"/>
      <inertia ixx="0.01" ixy="0.0" ixz="0.0" iyy="0.01" iyz="0.0" izz="0.01"/>
    </inertial>
    <visual name="upper_leg_visual">
      <origin rpy="0 0 0" xyz="0 0 0"/>
      <geometry>
        <mesh filename="file:///home/ws/ros_gz_example_description/models/neptr/meshes/thigh.stl" scale="1 1 1"/>
      </geometry>
      <material name="upper_leg_material">
        <color rgba="0.7 0.7 0.7 1"/>
      </material>
    </visual>
    <!-- Knee Visual -->
    <visual name="knee_joint_visual">
      <origin rpy="0 0 0" xyz="0 0 -0.4"/>
      <!-- Adjusted position relative to the upper leg -->
      <geometry>
        <mesh filename="file:///home/ws/ros_gz_example_description/models/neptr/meshes/knee.stl" scale="1 1 1"/>
      </geometry>
      <material name="knee_joint_material">
        <color rgba="0.2 0.5 0.8 1"/>
      </material>
    </visual>
  </link>
  <!-- Lower Leg -->
  <link name="lower_leg">
    <inertial>
      <origin rpy="0 0 0" xyz="0 0 0"/>
      <mass value="1.0"/>
      <inertia ixx="0.01" ixy="0.0" ixz="0.0" iyy="0.01" iyz="0.0" izz="0.01"/>
    </inertial>
    <visual name="lower_leg_visual">
      <origin rpy="0 0 0" xyz="0 0 -0.4"/>
      <geometry>
        <mesh filename="file:///home/ws/ros_gz_example_description/models/neptr/meshes/foot_link.stl" scale="1 1 1"/>
      </geometry>
      <material name="lower_leg_material">
        <color rgba="0.7 0.7 0.7 1"/>
      </material>
    </visual>
  </link>
  <!-- Foot -->
  <link name="foot">
    <inertial>
      <origin rpy="0 0 0" xyz="0 0 0"/>
      <mass value="0.5"/>
      <inertia ixx="0.005" ixy="0.0" ixz="0.0" iyy="0.005" iyz="0.0" izz="0.005"/>
    </inertial>
    <visual name="foot_visual">
      <origin rpy="0 0 0" xyz="0 0 -0.4"/>
      <geometry>
        <mesh filename="file:///home/ws/ros_gz_example_description/models/neptr/meshes/foot.stl" scale="1 1 1"/>
      </geometry>
      <material name="foot_material">
        <color rgba="1 0 0 1"/>
      </material>
    </visual>
  </link>
  <!-- Joints -->
  <joint name="knee_joint" type="revolute">
    <parent link="upper_leg"/>
    <child link="lower_leg"/>
    <origin rpy="0 0 0" xyz="0 0 -0.4"/>
    <axis xyz="0 1 0"/>
    <limit effort="100" lower="-1.57" upper="1.57" velocity="1.0"/>
  </joint>
  <joint name="ankle_joint" type="fixed">
    <parent link="lower_leg"/>
    <child link="foot"/>
    <origin rpy="0 0 0" xyz="0 0 -0.4"/>
  </joint>
</robot>
